[2025-03-30T10:25:58.854+0000] {local_task_job_runner.py:123} INFO - ::group::Pre task execution logs
[2025-03-30T10:25:59.025+0000] {taskinstance.py:2614} INFO - Dependencies all met for dep_context=non-requeueable deps ti=<TaskInstance: daily_weather_etl.run_main_script scheduled__2025-03-28T08:00:00+00:00 [queued]>
[2025-03-30T10:25:59.037+0000] {taskinstance.py:2614} INFO - Dependencies all met for dep_context=requeueable deps ti=<TaskInstance: daily_weather_etl.run_main_script scheduled__2025-03-28T08:00:00+00:00 [queued]>
[2025-03-30T10:25:59.039+0000] {taskinstance.py:2867} INFO - Starting attempt 1 of 2
[2025-03-30T10:25:59.065+0000] {taskinstance.py:2890} INFO - Executing <Task(BashOperator): run_main_script> on 2025-03-28 08:00:00+00:00
[2025-03-30T10:25:59.071+0000] {standard_task_runner.py:72} INFO - Started process 56 to run task
[2025-03-30T10:25:59.075+0000] {standard_task_runner.py:104} INFO - Running: ['***', 'tasks', 'run', 'daily_weather_etl', 'run_main_script', 'scheduled__2025-03-28T08:00:00+00:00', '--job-id', '142', '--raw', '--subdir', 'DAGS_FOLDER/weather_dag.py', '--cfg-path', '/tmp/tmp36xj4e_p']
[2025-03-30T10:25:59.077+0000] {standard_task_runner.py:105} INFO - Job 142: Subtask run_main_script
[2025-03-30T10:25:59.131+0000] {task_command.py:467} INFO - Running <TaskInstance: daily_weather_etl.run_main_script scheduled__2025-03-28T08:00:00+00:00 [running]> on host 3c3c1f66214b
[2025-03-30T10:25:59.222+0000] {taskinstance.py:3134} INFO - Exporting env vars: AIRFLOW_CTX_DAG_OWNER='***' AIRFLOW_CTX_DAG_ID='daily_weather_etl' AIRFLOW_CTX_TASK_ID='run_main_script' AIRFLOW_CTX_EXECUTION_DATE='2025-03-28T08:00:00+00:00' AIRFLOW_CTX_TRY_NUMBER='1' AIRFLOW_CTX_DAG_RUN_ID='scheduled__2025-03-28T08:00:00+00:00'
[2025-03-30T10:25:59.224+0000] {logging_mixin.py:190} INFO - Task instance is in running state
[2025-03-30T10:25:59.225+0000] {logging_mixin.py:190} INFO -  Previous state of the Task instance: queued
[2025-03-30T10:25:59.226+0000] {logging_mixin.py:190} INFO - Current task name:run_main_script state:running start_date:2025-03-30 10:25:59.027194+00:00
[2025-03-30T10:25:59.227+0000] {logging_mixin.py:190} INFO - Dag name:daily_weather_etl and current dag run status:running
[2025-03-30T10:25:59.227+0000] {taskinstance.py:732} INFO - ::endgroup::
[2025-03-30T10:25:59.229+0000] {subprocess.py:78} INFO - Tmp dir root location: /tmp
[2025-03-30T10:25:59.230+0000] {subprocess.py:88} INFO - Running command: ['/usr/bin/bash', '-c', 'python /opt/***/dags/main.py']
[2025-03-30T10:25:59.240+0000] {subprocess.py:99} INFO - Output:
[2025-03-30T10:26:00.227+0000] {subprocess.py:106} INFO - Traceback (most recent call last):
[2025-03-30T10:26:00.228+0000] {subprocess.py:106} INFO -   File "/opt/***/dags/main.py", line 3, in <module>
[2025-03-30T10:26:00.229+0000] {subprocess.py:106} INFO -     from utils import create_historical, check_city_minio
[2025-03-30T10:26:00.230+0000] {subprocess.py:106} INFO -   File "/opt/***/dags/utils.py", line 8, in <module>
[2025-03-30T10:26:00.231+0000] {subprocess.py:106} INFO -     from config import API_KEY
[2025-03-30T10:26:00.231+0000] {subprocess.py:106} INFO - ImportError: cannot import name 'API_KEY' from 'config' (/opt/***/dags/config.py)
[2025-03-30T10:26:00.302+0000] {subprocess.py:110} INFO - Command exited with return code 1
[2025-03-30T10:26:00.312+0000] {taskinstance.py:3313} ERROR - Task failed with exception
Traceback (most recent call last):
  File "/home/airflow/.local/lib/python3.9/site-packages/airflow/models/taskinstance.py", line 768, in _execute_task
    result = _execute_callable(context=context, **execute_callable_kwargs)
  File "/home/airflow/.local/lib/python3.9/site-packages/airflow/models/taskinstance.py", line 734, in _execute_callable
    return ExecutionCallableRunner(
  File "/home/airflow/.local/lib/python3.9/site-packages/airflow/utils/operator_helpers.py", line 252, in run
    return self.func(*args, **kwargs)
  File "/home/airflow/.local/lib/python3.9/site-packages/airflow/models/baseoperator.py", line 424, in wrapper
    return func(self, *args, **kwargs)
  File "/home/airflow/.local/lib/python3.9/site-packages/airflow/operators/bash.py", line 276, in execute
    raise AirflowException(
airflow.exceptions.AirflowException: Bash command failed. The command returned a non-zero exit code 1.
[2025-03-30T10:26:00.322+0000] {logging_mixin.py:190} INFO - Task instance in failure state
[2025-03-30T10:26:00.323+0000] {logging_mixin.py:190} INFO - Task start:2025-03-30 10:25:59.027194+00:00 end:2025-03-30 10:26:00.321954+00:00 duration:1.29476
[2025-03-30T10:26:00.324+0000] {logging_mixin.py:190} INFO - Task:<Task(BashOperator): run_main_script> dag:<DAG: daily_weather_etl> dagrun:<DagRun daily_weather_etl @ 2025-03-28 08:00:00+00:00: scheduled__2025-03-28T08:00:00+00:00, state:running, queued_at: 2025-03-30 10:25:51.880233+00:00. externally triggered: False>
[2025-03-30T10:26:00.325+0000] {logging_mixin.py:190} INFO - Failure caused by Bash command failed. The command returned a non-zero exit code 1.
[2025-03-30T10:26:00.325+0000] {taskinstance.py:1226} INFO - Marking task as UP_FOR_RETRY. dag_id=daily_weather_etl, task_id=run_main_script, run_id=scheduled__2025-03-28T08:00:00+00:00, execution_date=20250328T080000, start_date=20250330T102559, end_date=20250330T102600
[2025-03-30T10:26:00.354+0000] {taskinstance.py:341} INFO - ::group::Post task execution logs
[2025-03-30T10:26:00.355+0000] {standard_task_runner.py:124} ERROR - Failed to execute job 142 for task run_main_script (Bash command failed. The command returned a non-zero exit code 1.; 56)
Traceback (most recent call last):
  File "/home/airflow/.local/lib/python3.9/site-packages/airflow/task/task_runner/standard_task_runner.py", line 117, in _start_by_fork
    ret = args.func(args, dag=self.dag)
  File "/home/airflow/.local/lib/python3.9/site-packages/airflow/cli/cli_config.py", line 49, in command
    return func(*args, **kwargs)
  File "/home/airflow/.local/lib/python3.9/site-packages/airflow/utils/cli.py", line 116, in wrapper
    return f(*args, **kwargs)
  File "/home/airflow/.local/lib/python3.9/site-packages/airflow/cli/commands/task_command.py", line 483, in task_run
    task_return_code = _run_task_by_selected_method(args, _dag, ti)
  File "/home/airflow/.local/lib/python3.9/site-packages/airflow/cli/commands/task_command.py", line 256, in _run_task_by_selected_method
    return _run_raw_task(args, ti)
  File "/home/airflow/.local/lib/python3.9/site-packages/airflow/cli/commands/task_command.py", line 341, in _run_raw_task
    return ti._run_raw_task(
  File "/home/airflow/.local/lib/python3.9/site-packages/airflow/utils/session.py", line 97, in wrapper
    return func(*args, session=session, **kwargs)
  File "/home/airflow/.local/lib/python3.9/site-packages/airflow/models/taskinstance.py", line 3006, in _run_raw_task
    return _run_raw_task(
  File "/home/airflow/.local/lib/python3.9/site-packages/airflow/models/taskinstance.py", line 274, in _run_raw_task
    TaskInstance._execute_task_with_callbacks(
  File "/home/airflow/.local/lib/python3.9/site-packages/airflow/models/taskinstance.py", line 3161, in _execute_task_with_callbacks
    result = self._execute_task(context, task_orig)
  File "/home/airflow/.local/lib/python3.9/site-packages/airflow/models/taskinstance.py", line 3185, in _execute_task
    return _execute_task(self, context, task_orig)
  File "/home/airflow/.local/lib/python3.9/site-packages/airflow/models/taskinstance.py", line 768, in _execute_task
    result = _execute_callable(context=context, **execute_callable_kwargs)
  File "/home/airflow/.local/lib/python3.9/site-packages/airflow/models/taskinstance.py", line 734, in _execute_callable
    return ExecutionCallableRunner(
  File "/home/airflow/.local/lib/python3.9/site-packages/airflow/utils/operator_helpers.py", line 252, in run
    return self.func(*args, **kwargs)
  File "/home/airflow/.local/lib/python3.9/site-packages/airflow/models/baseoperator.py", line 424, in wrapper
    return func(self, *args, **kwargs)
  File "/home/airflow/.local/lib/python3.9/site-packages/airflow/operators/bash.py", line 276, in execute
    raise AirflowException(
airflow.exceptions.AirflowException: Bash command failed. The command returned a non-zero exit code 1.
[2025-03-30T10:26:00.412+0000] {local_task_job_runner.py:266} INFO - Task exited with return code 1
[2025-03-30T10:26:00.433+0000] {taskinstance.py:3901} INFO - 0 downstream tasks scheduled from follow-on schedule check
[2025-03-30T10:26:00.446+0000] {local_task_job_runner.py:245} INFO - ::endgroup::
