[2025-03-27T15:08:03.124+0000] {local_task_job_runner.py:123} INFO - ::group::Pre task execution logs
[2025-03-27T15:08:03.259+0000] {taskinstance.py:2614} INFO - Dependencies all met for dep_context=non-requeueable deps ti=<TaskInstance: daily_weather_etl.run_main_script manual__2025-03-27T15:08:01.390813+00:00 [queued]>
[2025-03-27T15:08:03.269+0000] {taskinstance.py:2614} INFO - Dependencies all met for dep_context=requeueable deps ti=<TaskInstance: daily_weather_etl.run_main_script manual__2025-03-27T15:08:01.390813+00:00 [queued]>
[2025-03-27T15:08:03.271+0000] {taskinstance.py:2867} INFO - Starting attempt 1 of 2
[2025-03-27T15:08:03.287+0000] {taskinstance.py:2890} INFO - Executing <Task(BashOperator): run_main_script> on 2025-03-27 15:08:01.390813+00:00
[2025-03-27T15:08:03.293+0000] {standard_task_runner.py:72} INFO - Started process 38943 to run task
[2025-03-27T15:08:03.297+0000] {standard_task_runner.py:104} INFO - Running: ['***', 'tasks', 'run', 'daily_weather_etl', 'run_main_script', 'manual__2025-03-27T15:08:01.390813+00:00', '--job-id', '123', '--raw', '--subdir', 'DAGS_FOLDER/weather_dag.py', '--cfg-path', '/tmp/tmp2zpmoijx']
[2025-03-27T15:08:03.299+0000] {standard_task_runner.py:105} INFO - Job 123: Subtask run_main_script
[2025-03-27T15:08:03.346+0000] {task_command.py:467} INFO - Running <TaskInstance: daily_weather_etl.run_main_script manual__2025-03-27T15:08:01.390813+00:00 [running]> on host 3c3c1f66214b
[2025-03-27T15:08:03.427+0000] {taskinstance.py:3134} INFO - Exporting env vars: AIRFLOW_CTX_DAG_OWNER='***' AIRFLOW_CTX_DAG_ID='daily_weather_etl' AIRFLOW_CTX_TASK_ID='run_main_script' AIRFLOW_CTX_EXECUTION_DATE='2025-03-27T15:08:01.390813+00:00' AIRFLOW_CTX_TRY_NUMBER='1' AIRFLOW_CTX_DAG_RUN_ID='manual__2025-03-27T15:08:01.390813+00:00'
[2025-03-27T15:08:03.429+0000] {logging_mixin.py:190} INFO - Task instance is in running state
[2025-03-27T15:08:03.430+0000] {logging_mixin.py:190} INFO -  Previous state of the Task instance: queued
[2025-03-27T15:08:03.432+0000] {logging_mixin.py:190} INFO - Current task name:run_main_script state:running start_date:2025-03-27 15:08:03.260830+00:00
[2025-03-27T15:08:03.433+0000] {logging_mixin.py:190} INFO - Dag name:daily_weather_etl and current dag run status:running
[2025-03-27T15:08:03.433+0000] {taskinstance.py:732} INFO - ::endgroup::
[2025-03-27T15:08:03.435+0000] {subprocess.py:78} INFO - Tmp dir root location: /tmp
[2025-03-27T15:08:03.437+0000] {subprocess.py:88} INFO - Running command: ['/usr/bin/bash', '-c', 'python /opt/***/dags/main.py']
[2025-03-27T15:08:03.445+0000] {subprocess.py:99} INFO - Output:
[2025-03-27T15:08:04.381+0000] {subprocess.py:106} INFO - Traceback (most recent call last):
[2025-03-27T15:08:04.382+0000] {subprocess.py:106} INFO -   File "/opt/***/dags/main.py", line 4, in <module>
[2025-03-27T15:08:04.383+0000] {subprocess.py:106} INFO -     from config import CITIEST
[2025-03-27T15:08:04.384+0000] {subprocess.py:106} INFO - ImportError: cannot import name 'CITIEST' from 'config' (/opt/***/dags/config.py)
[2025-03-27T15:08:04.443+0000] {subprocess.py:110} INFO - Command exited with return code 1
[2025-03-27T15:08:04.454+0000] {taskinstance.py:3313} ERROR - Task failed with exception
Traceback (most recent call last):
  File "/home/airflow/.local/lib/python3.9/site-packages/airflow/models/taskinstance.py", line 768, in _execute_task
    result = _execute_callable(context=context, **execute_callable_kwargs)
  File "/home/airflow/.local/lib/python3.9/site-packages/airflow/models/taskinstance.py", line 734, in _execute_callable
    return ExecutionCallableRunner(
  File "/home/airflow/.local/lib/python3.9/site-packages/airflow/utils/operator_helpers.py", line 252, in run
    return self.func(*args, **kwargs)
  File "/home/airflow/.local/lib/python3.9/site-packages/airflow/models/baseoperator.py", line 424, in wrapper
    return func(self, *args, **kwargs)
  File "/home/airflow/.local/lib/python3.9/site-packages/airflow/operators/bash.py", line 276, in execute
    raise AirflowException(
airflow.exceptions.AirflowException: Bash command failed. The command returned a non-zero exit code 1.
[2025-03-27T15:08:04.464+0000] {logging_mixin.py:190} INFO - Task instance in failure state
[2025-03-27T15:08:04.465+0000] {logging_mixin.py:190} INFO - Task start:2025-03-27 15:08:03.260830+00:00 end:2025-03-27 15:08:04.464144+00:00 duration:1.203314
[2025-03-27T15:08:04.467+0000] {logging_mixin.py:190} INFO - Task:<Task(BashOperator): run_main_script> dag:<DAG: daily_weather_etl> dagrun:<DagRun daily_weather_etl @ 2025-03-27 15:08:01.390813+00:00: manual__2025-03-27T15:08:01.390813+00:00, state:running, queued_at: 2025-03-27 15:08:01.406821+00:00. externally triggered: True>
[2025-03-27T15:08:04.468+0000] {logging_mixin.py:190} INFO - Failure caused by Bash command failed. The command returned a non-zero exit code 1.
[2025-03-27T15:08:04.470+0000] {taskinstance.py:1226} INFO - Marking task as UP_FOR_RETRY. dag_id=daily_weather_etl, task_id=run_main_script, run_id=manual__2025-03-27T15:08:01.390813+00:00, execution_date=20250327T150801, start_date=20250327T150803, end_date=20250327T150804
[2025-03-27T15:08:04.499+0000] {taskinstance.py:341} INFO - ::group::Post task execution logs
[2025-03-27T15:08:04.501+0000] {standard_task_runner.py:124} ERROR - Failed to execute job 123 for task run_main_script (Bash command failed. The command returned a non-zero exit code 1.; 38943)
Traceback (most recent call last):
  File "/home/airflow/.local/lib/python3.9/site-packages/airflow/task/task_runner/standard_task_runner.py", line 117, in _start_by_fork
    ret = args.func(args, dag=self.dag)
  File "/home/airflow/.local/lib/python3.9/site-packages/airflow/cli/cli_config.py", line 49, in command
    return func(*args, **kwargs)
  File "/home/airflow/.local/lib/python3.9/site-packages/airflow/utils/cli.py", line 116, in wrapper
    return f(*args, **kwargs)
  File "/home/airflow/.local/lib/python3.9/site-packages/airflow/cli/commands/task_command.py", line 483, in task_run
    task_return_code = _run_task_by_selected_method(args, _dag, ti)
  File "/home/airflow/.local/lib/python3.9/site-packages/airflow/cli/commands/task_command.py", line 256, in _run_task_by_selected_method
    return _run_raw_task(args, ti)
  File "/home/airflow/.local/lib/python3.9/site-packages/airflow/cli/commands/task_command.py", line 341, in _run_raw_task
    return ti._run_raw_task(
  File "/home/airflow/.local/lib/python3.9/site-packages/airflow/utils/session.py", line 97, in wrapper
    return func(*args, session=session, **kwargs)
  File "/home/airflow/.local/lib/python3.9/site-packages/airflow/models/taskinstance.py", line 3006, in _run_raw_task
    return _run_raw_task(
  File "/home/airflow/.local/lib/python3.9/site-packages/airflow/models/taskinstance.py", line 274, in _run_raw_task
    TaskInstance._execute_task_with_callbacks(
  File "/home/airflow/.local/lib/python3.9/site-packages/airflow/models/taskinstance.py", line 3161, in _execute_task_with_callbacks
    result = self._execute_task(context, task_orig)
  File "/home/airflow/.local/lib/python3.9/site-packages/airflow/models/taskinstance.py", line 3185, in _execute_task
    return _execute_task(self, context, task_orig)
  File "/home/airflow/.local/lib/python3.9/site-packages/airflow/models/taskinstance.py", line 768, in _execute_task
    result = _execute_callable(context=context, **execute_callable_kwargs)
  File "/home/airflow/.local/lib/python3.9/site-packages/airflow/models/taskinstance.py", line 734, in _execute_callable
    return ExecutionCallableRunner(
  File "/home/airflow/.local/lib/python3.9/site-packages/airflow/utils/operator_helpers.py", line 252, in run
    return self.func(*args, **kwargs)
  File "/home/airflow/.local/lib/python3.9/site-packages/airflow/models/baseoperator.py", line 424, in wrapper
    return func(self, *args, **kwargs)
  File "/home/airflow/.local/lib/python3.9/site-packages/airflow/operators/bash.py", line 276, in execute
    raise AirflowException(
airflow.exceptions.AirflowException: Bash command failed. The command returned a non-zero exit code 1.
[2025-03-27T15:08:04.518+0000] {local_task_job_runner.py:266} INFO - Task exited with return code 1
[2025-03-27T15:08:04.538+0000] {taskinstance.py:3901} INFO - 0 downstream tasks scheduled from follow-on schedule check
[2025-03-27T15:08:04.541+0000] {local_task_job_runner.py:245} INFO - ::endgroup::
