[2025-03-31T06:29:13.641+0000] {local_task_job_runner.py:123} INFO - ::group::Pre task execution logs
[2025-03-31T06:29:13.674+0000] {taskinstance.py:2614} INFO - Dependencies all met for dep_context=non-requeueable deps ti=<TaskInstance: daily_weather_etl.run_minio_script manual__2025-03-31T06:28:13.545022+00:00 [queued]>
[2025-03-31T06:29:13.689+0000] {taskinstance.py:2614} INFO - Dependencies all met for dep_context=requeueable deps ti=<TaskInstance: daily_weather_etl.run_minio_script manual__2025-03-31T06:28:13.545022+00:00 [queued]>
[2025-03-31T06:29:13.691+0000] {taskinstance.py:2867} INFO - Starting attempt 1 of 2
[2025-03-31T06:29:13.707+0000] {taskinstance.py:2890} INFO - Executing <Task(BashOperator): run_minio_script> on 2025-03-31 06:28:13.545022+00:00
[2025-03-31T06:29:13.714+0000] {standard_task_runner.py:72} INFO - Started process 1087 to run task
[2025-03-31T06:29:13.719+0000] {standard_task_runner.py:104} INFO - Running: ['***', 'tasks', 'run', 'daily_weather_etl', 'run_minio_script', 'manual__2025-03-31T06:28:13.545022+00:00', '--job-id', '168', '--raw', '--subdir', 'DAGS_FOLDER/weather_dag.py', '--cfg-path', '/tmp/tmpu2v46grf']
[2025-03-31T06:29:13.723+0000] {standard_task_runner.py:105} INFO - Job 168: Subtask run_minio_script
[2025-03-31T06:29:13.780+0000] {task_command.py:467} INFO - Running <TaskInstance: daily_weather_etl.run_minio_script manual__2025-03-31T06:28:13.545022+00:00 [running]> on host 3c3c1f66214b
[2025-03-31T06:29:14.118+0000] {taskinstance.py:3134} INFO - Exporting env vars: AIRFLOW_CTX_DAG_OWNER='***' AIRFLOW_CTX_DAG_ID='daily_weather_etl' AIRFLOW_CTX_TASK_ID='run_minio_script' AIRFLOW_CTX_EXECUTION_DATE='2025-03-31T06:28:13.545022+00:00' AIRFLOW_CTX_TRY_NUMBER='1' AIRFLOW_CTX_DAG_RUN_ID='manual__2025-03-31T06:28:13.545022+00:00'
[2025-03-31T06:29:14.120+0000] {logging_mixin.py:190} INFO - Task instance is in running state
[2025-03-31T06:29:14.121+0000] {logging_mixin.py:190} INFO -  Previous state of the Task instance: queued
[2025-03-31T06:29:14.122+0000] {logging_mixin.py:190} INFO - Current task name:run_minio_script state:running start_date:2025-03-31 06:29:13.675433+00:00
[2025-03-31T06:29:14.123+0000] {logging_mixin.py:190} INFO - Dag name:daily_weather_etl and current dag run status:running
[2025-03-31T06:29:14.125+0000] {taskinstance.py:732} INFO - ::endgroup::
[2025-03-31T06:29:14.127+0000] {subprocess.py:78} INFO - Tmp dir root location: /tmp
[2025-03-31T06:29:14.128+0000] {subprocess.py:88} INFO - Running command: ['/usr/bin/bash', '-c', 'python /opt/***/dags/minio.py']
[2025-03-31T06:29:14.146+0000] {subprocess.py:99} INFO - Output:
[2025-03-31T06:29:14.302+0000] {subprocess.py:106} INFO -   File "/opt/***/dags/minio.py", line 15
[2025-03-31T06:29:14.303+0000] {subprocess.py:106} INFO -     print(f"Ciudad: {city.get("city")}, latitud: {city.get("lat")}, longitud: {city.get("long")}")
[2025-03-31T06:29:14.305+0000] {subprocess.py:106} INFO -                                ^
[2025-03-31T06:29:14.306+0000] {subprocess.py:106} INFO - SyntaxError: f-string: unmatched '('
[2025-03-31T06:29:14.309+0000] {subprocess.py:110} INFO - Command exited with return code 1
[2025-03-31T06:29:14.321+0000] {taskinstance.py:3313} ERROR - Task failed with exception
Traceback (most recent call last):
  File "/home/airflow/.local/lib/python3.9/site-packages/airflow/models/taskinstance.py", line 768, in _execute_task
    result = _execute_callable(context=context, **execute_callable_kwargs)
  File "/home/airflow/.local/lib/python3.9/site-packages/airflow/models/taskinstance.py", line 734, in _execute_callable
    return ExecutionCallableRunner(
  File "/home/airflow/.local/lib/python3.9/site-packages/airflow/utils/operator_helpers.py", line 252, in run
    return self.func(*args, **kwargs)
  File "/home/airflow/.local/lib/python3.9/site-packages/airflow/models/baseoperator.py", line 424, in wrapper
    return func(self, *args, **kwargs)
  File "/home/airflow/.local/lib/python3.9/site-packages/airflow/operators/bash.py", line 276, in execute
    raise AirflowException(
airflow.exceptions.AirflowException: Bash command failed. The command returned a non-zero exit code 1.
[2025-03-31T06:29:14.332+0000] {logging_mixin.py:190} INFO - Task instance in failure state
[2025-03-31T06:29:14.334+0000] {logging_mixin.py:190} INFO - Task start:2025-03-31 06:29:13.675433+00:00 end:2025-03-31 06:29:14.331755+00:00 duration:0.656322
[2025-03-31T06:29:14.335+0000] {logging_mixin.py:190} INFO - Task:<Task(BashOperator): run_minio_script> dag:<DAG: daily_weather_etl> dagrun:<DagRun daily_weather_etl @ 2025-03-31 06:28:13.545022+00:00: manual__2025-03-31T06:28:13.545022+00:00, state:running, queued_at: 2025-03-31 06:28:13.560248+00:00. externally triggered: True>
[2025-03-31T06:29:14.337+0000] {logging_mixin.py:190} INFO - Failure caused by Bash command failed. The command returned a non-zero exit code 1.
[2025-03-31T06:29:14.338+0000] {taskinstance.py:1226} INFO - Marking task as UP_FOR_RETRY. dag_id=daily_weather_etl, task_id=run_minio_script, run_id=manual__2025-03-31T06:28:13.545022+00:00, execution_date=20250331T062813, start_date=20250331T062913, end_date=20250331T062914
[2025-03-31T06:29:14.413+0000] {taskinstance.py:341} INFO - ::group::Post task execution logs
[2025-03-31T06:29:14.417+0000] {standard_task_runner.py:124} ERROR - Failed to execute job 168 for task run_minio_script (Bash command failed. The command returned a non-zero exit code 1.; 1087)
Traceback (most recent call last):
  File "/home/airflow/.local/lib/python3.9/site-packages/airflow/task/task_runner/standard_task_runner.py", line 117, in _start_by_fork
    ret = args.func(args, dag=self.dag)
  File "/home/airflow/.local/lib/python3.9/site-packages/airflow/cli/cli_config.py", line 49, in command
    return func(*args, **kwargs)
  File "/home/airflow/.local/lib/python3.9/site-packages/airflow/utils/cli.py", line 116, in wrapper
    return f(*args, **kwargs)
  File "/home/airflow/.local/lib/python3.9/site-packages/airflow/cli/commands/task_command.py", line 483, in task_run
    task_return_code = _run_task_by_selected_method(args, _dag, ti)
  File "/home/airflow/.local/lib/python3.9/site-packages/airflow/cli/commands/task_command.py", line 256, in _run_task_by_selected_method
    return _run_raw_task(args, ti)
  File "/home/airflow/.local/lib/python3.9/site-packages/airflow/cli/commands/task_command.py", line 341, in _run_raw_task
    return ti._run_raw_task(
  File "/home/airflow/.local/lib/python3.9/site-packages/airflow/utils/session.py", line 97, in wrapper
    return func(*args, session=session, **kwargs)
  File "/home/airflow/.local/lib/python3.9/site-packages/airflow/models/taskinstance.py", line 3006, in _run_raw_task
    return _run_raw_task(
  File "/home/airflow/.local/lib/python3.9/site-packages/airflow/models/taskinstance.py", line 274, in _run_raw_task
    TaskInstance._execute_task_with_callbacks(
  File "/home/airflow/.local/lib/python3.9/site-packages/airflow/models/taskinstance.py", line 3161, in _execute_task_with_callbacks
    result = self._execute_task(context, task_orig)
  File "/home/airflow/.local/lib/python3.9/site-packages/airflow/models/taskinstance.py", line 3185, in _execute_task
    return _execute_task(self, context, task_orig)
  File "/home/airflow/.local/lib/python3.9/site-packages/airflow/models/taskinstance.py", line 768, in _execute_task
    result = _execute_callable(context=context, **execute_callable_kwargs)
  File "/home/airflow/.local/lib/python3.9/site-packages/airflow/models/taskinstance.py", line 734, in _execute_callable
    return ExecutionCallableRunner(
  File "/home/airflow/.local/lib/python3.9/site-packages/airflow/utils/operator_helpers.py", line 252, in run
    return self.func(*args, **kwargs)
  File "/home/airflow/.local/lib/python3.9/site-packages/airflow/models/baseoperator.py", line 424, in wrapper
    return func(self, *args, **kwargs)
  File "/home/airflow/.local/lib/python3.9/site-packages/airflow/operators/bash.py", line 276, in execute
    raise AirflowException(
airflow.exceptions.AirflowException: Bash command failed. The command returned a non-zero exit code 1.
[2025-03-31T06:29:14.478+0000] {local_task_job_runner.py:266} INFO - Task exited with return code 1
[2025-03-31T06:29:14.517+0000] {taskinstance.py:3901} INFO - 0 downstream tasks scheduled from follow-on schedule check
[2025-03-31T06:29:14.520+0000] {local_task_job_runner.py:245} INFO - ::endgroup::
