[2025-03-25T08:18:13.227+0000] {local_task_job_runner.py:123} INFO - ::group::Pre task execution logs
[2025-03-25T08:18:13.242+0000] {taskinstance.py:2614} INFO - Dependencies all met for dep_context=non-requeueable deps ti=<TaskInstance: daily_weather_etl.run_weather_script manual__2025-03-25T08:13:07.358075+00:00 [queued]>
[2025-03-25T08:18:13.250+0000] {taskinstance.py:2614} INFO - Dependencies all met for dep_context=requeueable deps ti=<TaskInstance: daily_weather_etl.run_weather_script manual__2025-03-25T08:13:07.358075+00:00 [queued]>
[2025-03-25T08:18:13.252+0000] {taskinstance.py:2867} INFO - Starting attempt 2 of 2
[2025-03-25T08:18:13.264+0000] {taskinstance.py:2890} INFO - Executing <Task(BashOperator): run_weather_script> on 2025-03-25 08:13:07.358075+00:00
[2025-03-25T08:18:13.269+0000] {standard_task_runner.py:72} INFO - Started process 182 to run task
[2025-03-25T08:18:13.273+0000] {standard_task_runner.py:104} INFO - Running: ['***', 'tasks', 'run', 'daily_weather_etl', 'run_weather_script', 'manual__2025-03-25T08:13:07.358075+00:00', '--job-id', '35', '--raw', '--subdir', 'DAGS_FOLDER/weather_dag.py', '--cfg-path', '/tmp/tmpapmqmv5n']
[2025-03-25T08:18:13.275+0000] {standard_task_runner.py:105} INFO - Job 35: Subtask run_weather_script
[2025-03-25T08:18:13.314+0000] {task_command.py:467} INFO - Running <TaskInstance: daily_weather_etl.run_weather_script manual__2025-03-25T08:13:07.358075+00:00 [running]> on host 469e12c37204
[2025-03-25T08:18:13.530+0000] {taskinstance.py:3134} INFO - Exporting env vars: AIRFLOW_CTX_DAG_OWNER='***' AIRFLOW_CTX_DAG_ID='daily_weather_etl' AIRFLOW_CTX_TASK_ID='run_weather_script' AIRFLOW_CTX_EXECUTION_DATE='2025-03-25T08:13:07.358075+00:00' AIRFLOW_CTX_TRY_NUMBER='2' AIRFLOW_CTX_DAG_RUN_ID='manual__2025-03-25T08:13:07.358075+00:00'
[2025-03-25T08:18:13.533+0000] {logging_mixin.py:190} INFO - Task instance is in running state
[2025-03-25T08:18:13.534+0000] {logging_mixin.py:190} INFO -  Previous state of the Task instance: queued
[2025-03-25T08:18:13.535+0000] {logging_mixin.py:190} INFO - Current task name:run_weather_script state:running start_date:2025-03-25 08:18:13.243864+00:00
[2025-03-25T08:18:13.537+0000] {logging_mixin.py:190} INFO - Dag name:daily_weather_etl and current dag run status:running
[2025-03-25T08:18:13.538+0000] {taskinstance.py:732} INFO - ::endgroup::
[2025-03-25T08:18:13.539+0000] {subprocess.py:78} INFO - Tmp dir root location: /tmp
[2025-03-25T08:18:13.540+0000] {subprocess.py:88} INFO - Running command: ['/usr/bin/bash', '-c', 'spark-submit /opt/***/dags/main.py']
[2025-03-25T08:18:13.551+0000] {subprocess.py:99} INFO - Output:
[2025-03-25T08:18:13.608+0000] {subprocess.py:106} INFO - Error: Could not find or load main class org.apache.spark.launcher.Main
[2025-03-25T08:18:13.609+0000] {subprocess.py:106} INFO - Caused by: java.lang.ClassNotFoundException: org.apache.spark.launcher.Main
[2025-03-25T08:18:13.615+0000] {subprocess.py:106} INFO - /opt/spark/bin/spark-class: line 97: CMD: bad array subscript
[2025-03-25T08:18:13.616+0000] {subprocess.py:110} INFO - Command exited with return code 1
[2025-03-25T08:18:13.625+0000] {taskinstance.py:3313} ERROR - Task failed with exception
Traceback (most recent call last):
  File "/home/airflow/.local/lib/python3.9/site-packages/airflow/models/taskinstance.py", line 768, in _execute_task
    result = _execute_callable(context=context, **execute_callable_kwargs)
  File "/home/airflow/.local/lib/python3.9/site-packages/airflow/models/taskinstance.py", line 734, in _execute_callable
    return ExecutionCallableRunner(
  File "/home/airflow/.local/lib/python3.9/site-packages/airflow/utils/operator_helpers.py", line 252, in run
    return self.func(*args, **kwargs)
  File "/home/airflow/.local/lib/python3.9/site-packages/airflow/models/baseoperator.py", line 424, in wrapper
    return func(self, *args, **kwargs)
  File "/home/airflow/.local/lib/python3.9/site-packages/airflow/operators/bash.py", line 276, in execute
    raise AirflowException(
airflow.exceptions.AirflowException: Bash command failed. The command returned a non-zero exit code 1.
[2025-03-25T08:18:13.628+0000] {logging_mixin.py:190} INFO - Task instance in failure state
[2025-03-25T08:18:13.630+0000] {logging_mixin.py:190} INFO - Task start:2025-03-25 08:18:13.243864+00:00 end:2025-03-25 08:18:13.628535+00:00 duration:0.384671
[2025-03-25T08:18:13.631+0000] {logging_mixin.py:190} INFO - Task:<Task(BashOperator): run_weather_script> dag:<DAG: daily_weather_etl> dagrun:<DagRun daily_weather_etl @ 2025-03-25 08:13:07.358075+00:00: manual__2025-03-25T08:13:07.358075+00:00, state:running, queued_at: 2025-03-25 08:13:07.372775+00:00. externally triggered: True>
[2025-03-25T08:18:13.632+0000] {logging_mixin.py:190} INFO - Failure caused by Bash command failed. The command returned a non-zero exit code 1.
[2025-03-25T08:18:13.633+0000] {taskinstance.py:1226} INFO - Marking task as FAILED. dag_id=daily_weather_etl, task_id=run_weather_script, run_id=manual__2025-03-25T08:13:07.358075+00:00, execution_date=20250325T081307, start_date=20250325T081813, end_date=20250325T081813
[2025-03-25T08:18:13.656+0000] {taskinstance.py:341} INFO - ::group::Post task execution logs
[2025-03-25T08:18:13.657+0000] {standard_task_runner.py:124} ERROR - Failed to execute job 35 for task run_weather_script (Bash command failed. The command returned a non-zero exit code 1.; 182)
Traceback (most recent call last):
  File "/home/airflow/.local/lib/python3.9/site-packages/airflow/task/task_runner/standard_task_runner.py", line 117, in _start_by_fork
    ret = args.func(args, dag=self.dag)
  File "/home/airflow/.local/lib/python3.9/site-packages/airflow/cli/cli_config.py", line 49, in command
    return func(*args, **kwargs)
  File "/home/airflow/.local/lib/python3.9/site-packages/airflow/utils/cli.py", line 116, in wrapper
    return f(*args, **kwargs)
  File "/home/airflow/.local/lib/python3.9/site-packages/airflow/cli/commands/task_command.py", line 483, in task_run
    task_return_code = _run_task_by_selected_method(args, _dag, ti)
  File "/home/airflow/.local/lib/python3.9/site-packages/airflow/cli/commands/task_command.py", line 256, in _run_task_by_selected_method
    return _run_raw_task(args, ti)
  File "/home/airflow/.local/lib/python3.9/site-packages/airflow/cli/commands/task_command.py", line 341, in _run_raw_task
    return ti._run_raw_task(
  File "/home/airflow/.local/lib/python3.9/site-packages/airflow/utils/session.py", line 97, in wrapper
    return func(*args, session=session, **kwargs)
  File "/home/airflow/.local/lib/python3.9/site-packages/airflow/models/taskinstance.py", line 3006, in _run_raw_task
    return _run_raw_task(
  File "/home/airflow/.local/lib/python3.9/site-packages/airflow/models/taskinstance.py", line 274, in _run_raw_task
    TaskInstance._execute_task_with_callbacks(
  File "/home/airflow/.local/lib/python3.9/site-packages/airflow/models/taskinstance.py", line 3161, in _execute_task_with_callbacks
    result = self._execute_task(context, task_orig)
  File "/home/airflow/.local/lib/python3.9/site-packages/airflow/models/taskinstance.py", line 3185, in _execute_task
    return _execute_task(self, context, task_orig)
  File "/home/airflow/.local/lib/python3.9/site-packages/airflow/models/taskinstance.py", line 768, in _execute_task
    result = _execute_callable(context=context, **execute_callable_kwargs)
  File "/home/airflow/.local/lib/python3.9/site-packages/airflow/models/taskinstance.py", line 734, in _execute_callable
    return ExecutionCallableRunner(
  File "/home/airflow/.local/lib/python3.9/site-packages/airflow/utils/operator_helpers.py", line 252, in run
    return self.func(*args, **kwargs)
  File "/home/airflow/.local/lib/python3.9/site-packages/airflow/models/baseoperator.py", line 424, in wrapper
    return func(self, *args, **kwargs)
  File "/home/airflow/.local/lib/python3.9/site-packages/airflow/operators/bash.py", line 276, in execute
    raise AirflowException(
airflow.exceptions.AirflowException: Bash command failed. The command returned a non-zero exit code 1.
[2025-03-25T08:18:13.687+0000] {local_task_job_runner.py:266} INFO - Task exited with return code 1
[2025-03-25T08:18:13.710+0000] {taskinstance.py:3901} INFO - 0 downstream tasks scheduled from follow-on schedule check
[2025-03-25T08:18:13.718+0000] {local_task_job_runner.py:245} INFO - ::endgroup::
